Workbook

Sheet Summary Sheet 
A1: UPS | B1: 42917 | C1: 42948 | D1: 42979 | E1: 43009 | F1: 43040 | G1: 43070 | H1: 43101 | I1: 43132 | J1: Comments | K1: 43160 | L1: Comments | M1: 43282 | N1: Comments | O1: 43320 | P1: Comments | Q1: 24-10-2018 | R1: Comments | S1: 21-1-2019 | T1: Comments | U1: 27/8/2019 | V1: Comments | W1: 27/9/2019 | X1: Comments | Y1: 43565 | Z1: Comments | AA1: 31/10/2019 | AB1: Comments | AC1: 26/11/2019 | AD1: Comments | AE1: 44147 | AF1: Comments | AG1: 44321 | AH1: Comments
A2: AMAT | B2: 2 | C2: 2 | F2: 5 | H2: 4 | J2: Only Failed Batteries Considered. Not Changed | N2: To Be Checked | P2: To Be Checked | T2: Many Batteries reading not even coming | V2: Many reading not coming. UPS not in use | X2: Not Taken. UPS not in use. | AB2: Not Taken. UPS not in use. | AD2: Not Taken. UPS not in use. | AF2: Not Taken. UPS not in use. | AH2: Not Taken. UPS not in use.
A3: NANO | C3: 4 | J3: Only 5 "Warning" Batteries were replaced in Jan 2018 | K3: 26/3/2018 | L3: 32 new batteries installed on the second battery bank and old batteries removed. | M3: 0 | N3: All Pass | P3: To Be Checked | S3: 64 | T3: All Pass | U3: 64 | V3: All Pass | W3: 1 | X3: 1 Battery showing Failed | AA3: 64 | AB3: All Pass | AC3: 64 | AD3: All Pass | AE3: ='NANO '!AJ69 -> 64 | AF3: All Pass | AG3: ='NANO '!AL69 -> 64 | AH3: All Pass
A4: M1/M2 | M4: 16 | N4: In Warning Stage | P4: To Be Checked | S4: 83 | T4: 5 Batteries showing Failed & 78 Batteries showing Warning | U4: 5 | V4: 3 Warning & 2 Failed , Remaining 115 Passed. Battery Bank was fully changed on 3&4 August 2019 | W4: 8 | X4: 8 Batteries showing Failed | AA4: 9 | AB4: 4 Batteries showing Warning & 5 Batteries showing Failed | AC4: 15 | AD4: 2 Batteries showing Warning & 13 Batteries showing Failed | AE4: ='MICRO 1 & 2 '!X128 -> 27 | AF4: 2 Batteries showing Warning & 25 Batteries showing Failed | AH4: Need to be taken
A5: MBE | B5: 2 | E5: 0 | F5: 1 | J5: 2 Batteries replace in October. 1 required to be changed as no reading is coming. | N5: To Be Checked | O5: 0 | P5: All Pass | S5: 3 | T5: 2 Showing Failed & Battery reading did not come | U5: 1 | V5: 1 Battery reading did not come. Rest are Passed. | W5: 1 | X5: 1 Battery reading did not come. Rest are Passed. | AA5: 2 | AB5: 1 Battery showing Warning & 1 Battery reading did not come | AC5: 1 | AD5: 1 Battery showing Failed | AE5: ='MBE '!Y129 -> 58 | AF5: 34 Batteries showing Warning & 24 Batteries showing Failed | AG5: ='MBE '!AE129 -> 80
A6: NCPRE | F6: 1 | H6: 0 | J6: Replaced on 2/2/2018 | N6: To Be Checked | O6: 0 | P6: All Pass | S6: 1 | T6: 1 Battery reading did not come | U6: 120 | V6: All Pass | W6: 1 | X6: 1 Battery reading did not come | AA6: 1 | AB6: 1 Battery showing Warning | AC6: 1 | AD6: 1 Battery showing Warning | AE6: ='NCPRE '!T129 -> 14 | AF6: 8 Batteries showing Warning & 6 Batteries showing Failed | AG6: ='NCPRE '!V129 -> 21
A7: NMPF | Y7: 44 | Z7: All Pass
A8: AL & PC CELL MBE LAB LAHA SIR 10 KVA UPS
A9: GAL 6 SC SIR MBE LAB 10 KVA UPS
A10: GAL EURO MBE LAB LAHA SIR 10 KVA UPS
A11: EC Lab 10 KVA UPS
A12: MCL UPS 1 15 KVA
A13: MCL UPS 2 15 KVA
A14: IT Team Office 6 KVA UPS
A15: Micro 2 Lab XPS 10 KVA UPS
A16: HSC [OE] [NCPRE] Lab UPS - Newly Added

Sheet Reference Sheet
A1: Battery Internal Resistance [IR] Specs by Voltage & AH [Ampere Hours]
A2: Sr. No. | B2: Voltage | C2: AH | D2: Max IR (m-ohm)
A3: 1 | B3: 12 | C3: 7 | D3: 22
A4: 2 | B4: 12 | C4: 9 | D4: 18
A5: 3 | B5: 12 | C5: 12 | D5: 16
A6: 4 | B6: 12 | C6: 17 | D6: 15
A7: 5 | B7: 12 | C7: 26 | D7: 10
A8: 6 | B8: 12 | C8: 42 | D8: 8
A9: 7 | B9: 12 | C9: 65 | D9: 8
A10: 8 | B10: 12 | C10: 75 | D10: 8
A11: 9 | B11: 12 | C11: 100 | D11: 6
A12: 10 | B12: 12 | C12: 120 | D12: 6
A13: 11 | B13: 12 | C13: 150 | D13: 6
A14: 12 | B14: 12 | C14: 200 | D14: 5
A16: LEGEND/KEY
A17: Pass | B17: Below 1.5 x Max IR
A18: Warning | B18: Between 1.5 x Max IR to 2.0 x Max IR
A19: Fail | B19: Above 2.0 x Max IR

Sheet AMAT 
A1: Battery Spec: 12 Volts 120 AH
A2: Brand: Exide Powersafe
A3: Sr. No. | B3: 42937 | C3: 31/8/2017 | D3: 15/11/2017 | E3: 43374 | F3: Comments - 10/1/2017
A4: 1 | B4: 4.5 | C4: 6.1 | D4: 6.4 | E4: 4.9 | F4: PASS
A5: 2 | B5: 4.4 | C5: 4.6 | D5: 4.5 | E5: 4.6 | F5: PASS
A6: 3 | B6: 4.2 | C6: 4.3 | D6: 9999 | E6: OF. | F6: 5.6 came as reading in 2nd attempt - PASS
A7: 4 | B7: 3.9 | C7: 3.9 | D7: 3.8 | E7: 4 | F7: PASS
A8: 5 | B8: 12.5 | C8: 30 | D8: 77.6 | E8: 24.5 | F8: FAIL
A9: 6 | B9: 5.7 | C9: 5.5 | D9: 5.2 | E9: 4.1 | F9: PASS
A10: 7 | B10: 3.4 | C10: 3.6 | D10: 3.8 | E10: 4.8 | F10: PASS
A11: 8 | B11: 4.5 | C11: 5.1 | D11: 5.1 | E11: 4.3 | F11: PASS
A12: 9 | B12: 4.6 | C12: 5.2 | D12: 5 | E12: 4.9 | F12: PASS
A13: 10 | B13: 5 | C13: 5.1 | D13: 4.5 | E13: 3.9 | F13: PASS
A14: 11 | B14: 4.6 | C14: 5.4 | D14: 4.5 | E14: 5.3 | F14: PASS
A15: 12 | B15: 3.7 | C15: 3.8 | D15: 3.9 | E15: 4.6 | F15: PASS
A16: 13 | B16: 5.6 | C16: 5.4 | D16: 5.7 | E16: 3.8 | F16: PASS
A17: 14 | B17: 5.4 | C17: 5.2 | D17: 4.8 | E17: 4.7 | F17: PASS
A18: 15 | B18: 5.1 | C18: 4.8 | D18: 4.8 | E18: 5.2 | F18: PASS
... A79: 76 | B79: 4.5 | C79: 5.2 | D79: 4.7 | E79: 6.5 | F79: PASS
A80: 77 | B80: 4.6 | C80: 4.4 | D80: 4.8 | E80: OF. | F80: 4.9 came as reading in 2nd attempt - PASS
A81: 78 | B81: 5.2 | C81: 5.8 | D81: 4.5 | E81: 5.9 | F81: PASS
A82: 79 | B82: 4.2 | C82: 3.9 | D82: 4 | E82: 4.8 | F82: PASS
A83: 80 | B83: 6.1 | C83: 6.2 | D83: 4.8 | E83: 3.7 | F83: PASS
A84: 81 | B84: 4.2 | C84: 3.9 | D84: 4.1 | E84: 4.5 | F84: PASS
A85: 82 | B85: 6.5 | C85: 5.7 | D85: 4.5 | E85: 4.8 | F85: PASS
A86: 83 | B86: 5.2 | C86: 5.5 | D86: 4.6 | E86: 4.8 | F86: PASS
A87: 84 | B87: 4.8 | C87: 5.1 | D87: 4.3 | E87: 3.6 | F87: PASS
A88: 85 | B88: 4.1 | C88: 3.8 | D88: 4 | E88: 4.5 | F88: PASS
A89: 86 | B89: 4.9 | C89: 6.4 | D89: 5.4 | E89: 4.7 | F89: PASS
A90: 87 | B90: 6.1 | C90: 5.4 | D90: 4.7 | E90: 4.4 | F90: PASS
A91: 88 | B91: 5 | C91: 5.1 | D91: 4.2 | E91: 3.9 | F91: PASS
A92: 89 | B92: 4.6 | C92: 5.4 | D92: 4.8 | E92: 5.2 | F92: PASS
... A123: 120 | B123: 5.4 | C123: 5.9 | D123: 4.5 | E123: 4.6 | F123: PASS

Sheet NANO 
A1: Battery Spec: 12 Volts 150 AH
A2: Brand: Exide Powersafe
A3: Sr.No. | B3: 42937 | C3: 30/8/2017 | D3: 15/11/2017 | E3: 20/12/2017 | F3: Comments - 20/12/2018 | G3: 43374 | H3: Comments - 10/1/2018 | I3: 43405 | J3: Comments - 11/1/2018 | K3: 43345 | L3: Comments - 9/2/2018 | M3: New Battery Reading | N3: 19/2/2018 | O3: Comments - 19/2/2018 | P3: 26/3/2018 | Q3: Comments - 26/3/2018 | R3: 43166 | S3: Comments - 3/7/2018 | T3: 24/10/2018 | U3: Comments - 24/10/2018 | V3: 21/1/2019 | W3: Comments - 21/1/2019 | X3: 19/8/2019 | Y3: Comments - 19/8/2019 | Z3: 27/9/2019 | AA3: Comments - 27/9/2019 | AB3: 31/10/2019 | AC3: Comments - 31/10/2019 | AD3: 26/11/2019 | AE3: Comments - 26/11/2019 | AF3: 44075 | AG3: Comments - 9/1/2020 | AH3: 25/2/2020 | AI3: Comments - 25/2/2020 | AJ3: 44024 | AK3: Comments - 7/12/2020 | AL3: 25/1/2021 | AM3: Comments - 25/1/2021 | AN3: 44442 | AO3: Comments - 9/3/2021 | AP3: 27/4/2021 | AQ3: Comments - 27/4/2021
A4: 1 | B4: 7.3 | C4: 8.7 | D4: 3.2 | E4: 2.4 | F4: PASS | G4: 3.7 | H4: Pass | K4: 3 | N4: 3.3 | R4: 3 | S4: Pass | T4: 2.9 | U4: Pass | V4: 2.7 | W4: Pass | X4: 3.1 | Y4: Pass | Z4: 2.8 | AA4: Pass | AB4: 3 | AC4: Pass | AD4: 2.9 | AE4: Pass | AF4: 5.52 | AG4: Pass | AH4: 2.93 | AI4: Pass | AJ4: 3.05 | AK4: Pass | AL4: 3.26 | AM4: Pass | AN4: 3.26 | AO4: Pass | AP4: 3.6 | AQ4: Pass
A5: 2 | B5: 4.9 | C5: 9.1 | D5: 3.2 | E5: 3.1 | F5: PASS | G5: 3.1 | H5: Pass | K5: 3.2 | N5: 3 | R5: 3.9 | S5: Pass | T5: 3.1 | U5: Pass | V5: 3 | W5: Pass | X5: 2.7 | Y5: Pass | Z5: 3.3 | AA5: Pass | AB5: 3.2 | AC5: Pass | AD5: 2.8 | AE5: Pass | AF5: 6.56 | AG5: Pass | AH5: 3.63 | AI5: Pass | AJ5: 3.33 | AK5: Pass | AL5: 3.27 | AM5: Pass | AN5: 3.4 | AO5: Pass | AP5: 4.2 | AQ5: Pass
A6: 3 | B6: 2.5 | C6: 2.7 | D6: 3.5 | E6: 3.1 | F6: PASS | G6: 3.3 | H6: Pass | K6: 3.3 | N6: 3.7 | R6: 3.2 | S6: Pass | T6: 3.3 | U6: Pass | V6: 3.2 | W6: Pass | X6: 3.3 | Y6: Pass | Z6: 3.7 | AA6: Pass | AB6: 3.2 | AC6: Pass | AD6: 2.5 | AE6: Pass | AF6: 5.74 | AG6: Pass | AH6: 3.34 | AI6: Pass | AJ6: 3.36 | AK6: Pass | AL6: 3.38 | AM6: Pass | AN6: 3.43 | AO6: Pass | AP6: 3.2 | AQ6: Pass
A7: 4 | B7: 6.2 | C7: 7.1 | D7: 7.1 | E7: 6.6 | F7: PASS | G7: 8.6 | H7: Pass | K7: 9 | L7: Replaced during Nano AHU & Chiller PM | M7: 2.3 | N7: 3.1 | R7: 2.9 | S7: Pass | T7: 3.2 | U7: Pass | V7: 3.7 | W7: Pass | X7: 2.7 | Y7: Pass | Z7: 3.5 | AA7: Pass | AB7: 3.4 | AC7: Pass | AD7: 3.6 | AE7: Pass | AF7: 6.8 | AG7: Pass | AH7: 3.19 | AI7: Pass | AJ7: 3.45 | AK7: Pass | AL7: 3.43 | AM7: Pass | AN7: 3.51 | AO7: Pass | AP7: 3.5 | AQ7: Pass
A8: 5 | B8: 9.8 | C8: 71.8 | D8: 9.4 | E8: 7.9 | F8: PASS | G8: 8.4 | H8: Pass | K8: 8.6 | N8: 8.2 | R8: 3.5 | S8: Pass | T8: 3.4 | U8: Pass | V8: 2.6 | W8: Pass | X8: 3.1 | Y8: Pass | Z8: 2.8 | AA8: Pass | AB8: 2.9 | AC8: Pass | AD8: 3.5 | AE8: Pass | AF8: 6.07 | AG8: Pass | AH8: 3.51 | AI8: Pass | AJ8: 3.19 | AK8: Pass | AL8: 3.25 | AM8: Pass | AN8: 3.29 | AO8: Pass | AP8: 4 | AQ8: Pass
A9: 6 | B9: 7.7 | C9: 8.2 | D9: 7.2 | E9: 8 | F9: PASS | G9: 9.7 | H9: Warning | I9: 2.5 | J9: Replaced with new one | K9: 3 | N9: 3.3 | R9: 3.5 | S9: Pass | T9: 3.2 | U9: Pass | V9: 3.3 | W9: Pass | X9: 3.1 | Y9: Pass | Z9: 7.5 | AA9: Pass | AB9: 3 | AC9: Pass | AD9: 3.2 | AE9: Pass | AG9: No Reading Came | AH9: 3.34 | AI9: Pass | AJ9: 3.31 | AK9: Pass | AL9: 3.41 | AM9: Pass | AN9: 3.48 | AO9: Pass | AP9: 2.5 | AQ9: Pass
A10: 7 | B10: 7.2 | C10: 6.8 | D10: 6.9 | E10: 7.4 | F10: PASS | G10: 10.5 | H10: Warning | I10: 2.8 | J10: Replaced with new one | K10: 2.8 | N10: 3.2 | R10: 2.8 | S10: Pass | T10: 2.9 | U10: Pass | V10: 3 | W10: Pass | X10: 3 | Y10: Pass | Z10: 2.9 | AA10: Pass | AB10: 3.2 | AC10: Pass | AD10: 2.7 | AE10: Pass | AF10: 5.25 | AG10: Pass | AH10: 2.97 | AI10: Pass | AJ10: 3.13 | AK10: Pass | AL10: 3.25 | AM10: Pass | AN10: 3.23 | AO10: Pass | AP10: 3.4 | AQ10: Pass
A11: 8 | B11: 5.8 | C11: 10 | D11: 9.6 | E11: 9.7 | F11: WARNING | G11: 2.9 | H11: Pass | K11: 3.1 | N11: 3.2 | R11: 3.9 | S11: Pass | T11: 2.6 | U11: Pass | V11: 2.6 | W11: Pass | X11: 3.4 | Y11: Pass | Z11: 3.2 | AA11: Pass | AB11: 3.2 | AC11: Pass | AD11: 3.1 | AE11: Pass | AF11: 3.09 | AG11: Pass | AH11: 3.23 | AI11: Pass | AJ11: 3.24 | AK11: Pass | AL11: 3.2 | AM11: Pass | AN11: 3.22 | AO11: Pass | AP11: 3.1 | AQ11: Pass
A12: 9 | B12: 7.5 | C12: 10.6 | D12: 8.3 | E12: 8.6 | F12: PASS | G12: 6.8 | H12: Pass | K12: 7.3 | N12: 7.9 | R12: 3.6 | S12: Pass | T12: 3.5 | U12: Pass | V12: 3.1 | W12: Pass | X12: 2.9 | Y12: Pass | Z12: 3.4 | AA12: Pass | AB12: 3.3 | AC12: Pass | AD12: 4 | AE12: Pass | AF12: 3.32 | AG12: Pass | AH12: 3.55 | AI12: Pass | AJ12: 3.28 | AK12: Pass | AL12: 3.36 | AM12: Pass | AN12: 3.4 | AO12: Pass | AP12: 2.9 | AQ12: Pass
A13: 10 | B13: 8.3 | C13: 7.9 | D13: 3.3 | E13: 3.3 | F13: PASS | G13: 8.1 | H13: Pass | K13: 7.5 | N13: 7 | R13: 3.3 | S13: Pass | T13: 3 | U13: Pass | V13: 3.2 | W13: Pass | X13: 3.3 | Y13: Pass | Z13: 3.1 | AA13: Pass | AB13: 3.2 | AC13: Pass | AD13: 3.1 | AE13: Pass | AF13: 3.11 | AG13: Pass | AH13: 3.65 | AI13: Pass | AJ13: 3.22 | AK13: Pass | AL13: 3.46 | AM13: Pass | AN13: 3.43 | AO13: Pass | AP13: 3.2 | AQ13: Pass
A14: 11 | B14: 7.3 | C14: 6.3 | D14: 3.2 | E14: 3.1 | F14: PASS | G14: 8.7 | H14: Pass | K14: 8.9 | N14: 10.2 | O14: Warning | R14: 3.4 | S14: Pass | T14: 2.8 | U14: Pass | V14: 3 | W14: Pass | X14: 2.8 | Y14: Pass | Z14: 3.2 | AA14: Pass | AB14: 3.3 | AC14: Pass | AD14: 3 | AE14: Pass | AF14: 3.08 | AG14: Pass | AH14: 3.55 | AI14: Pass | AJ14: 3.14 | AK14: Pass | AL14: 3.36 | AM14: Pass | AN14: 3.31 | AO14: Pass | AP14: 3.5 | AQ14: Pass
A15: 12 | B15: 5.7 | C15: 6.7 | D15: 3.3 | E15: 2.6 | F15: PASS | G15: 3.1 | H15: Pass | K15: 3 | N15: 3.2 | R15: 3 | S15: Pass | T15: 3.3 | U15: Pass | V15: 3 | W15: Pass | X15: 2.6 | Y15: Pass | Z15: 3.2 | AA15: Pass | AB15: 3.3 | AC15: Pass | AD15: 3.1 | AE15: Pass | AF15: 3.61 | AG15: Pass | AH15: 3.09 | AI15: Pass | AJ15: 3.15 | AK15: Pass | AL15: 3.25 | AM15: Pass | AN15: 3.44 | AO15: Pass | AP15: 3.6 | AQ15: Pass
A16: 13 | B16: 6 | C16: 6 | D16: 3 | E16: 3.2 | F16: PASS | G16: 9 | H16: Warning | J16: Replacement pending | K16: 3.7 | N16: 3.6 | R16: 3.4 | S16: Pass | T16: 3.6 | U16: Pass | V16: 2.5 | W16: Pass | X16: 2.7 | Y16: Pass | Z16: 3.1 | AA16: Pass | AB16: 3.1 | AC16: Pass | AD16: 2.4 | AE16: Pass | AF16: 3.16 | AG16: Pass | AH16: 3.66 | AI16: Pass | AJ16: 3.3 | AK16: Pass | AL16: 3.34 | AM16: Pass | AN16: 3.33 | AO16: Pass | AP16: 3.4 | AQ16: Pass
A17: 14 | B17: 8 | C17: 7 | D17: 7.8 | E17: 8.9 | F17: PASS | G17: 7.6 | H17: Pass | K17: 10.3 | L17: Replaced during Nano AHU & Chiller PM | M17: 2.1 | N17: 3.4 | R17: 3.1 | S17: Pass | T17: 3.1 | U17: Pass | V17: 2.9 | W17: Pass | X17: 3.1 | Y17: Pass | Z17: 3 | AA17: Pass | AB17: 2.9 | AC17: Pass | AD17: 2.8 | AE17: Pass | AF17: 2.79 | AG17: Pass | AH17: 2.95 | AI17: Pass | AJ17: 3.15 | AK17: Pass | AL17: 3.28 | AM17: Pass | AN17: 3.15 | AO17: Pass | AP17: 3.7 | AQ17: Pass
A18: 15 | B18: 6.3 | C18: 7.2 | D18: 6.7 | E18: 8.3 | F18: PASS | G18: 7.4 | H18: Pass | K18: 9.1 | L18: Replaced during Nano AHU & Chiller PM | M18: 2.3 | N18: 3.4 | R18: 2.7 | S18: Pass | T18: 3.5 | U18: Pass | V18: 3.1 | W18: Pass | X18: 2.8 | Y18: Pass | Z18: 3 | AA18: Pass | AB18: 3.4 | AC18: Pass | AD18: 3.2 | AE18: Pass | AF18: 2.84 | AG18: Pass | AH18: 3.35 | AI18: Pass | AJ18: 3.27 | AK18: Pass | AL18: 3.28 | AM18: Pass | AN18: 3.38 | AO18: Pass | AP18: 2.8 | AQ18: Pass
A19: 16 | B19: 6.3 | C19: 8.4 | D19: 3.3 | E19: 3.2 | F19: PASS | G19: 10.5 | H19: Warning | I19: 2.7 | J19: Replaced with new one | K19: 7.4 | N19: 7.3 | R19: 3.3 | S19: Pass | T19: 3.1 | U19: Pass | V19: 3.1 | W19: Pass | X19: 2.3 | Y19: Pass | Z19: 2.6 | AA19: Pass | AB19: 3.2 | AC19: Pass | AD19: 3.1 | AE19: Pass | AF19: 3.68 | AG19: Pass | AH19: 3.37 | AI19: Pass | AJ19: 3.44 | AK19: Pass | AL19: 3.39 | AM19: Pass | AN19: 3.44 | AO19: Pass | AP19: 3.6 | AQ19: Pass
A20: 17 | B20: 6.8 | C20: 4 | D20: 7.4 | E20: 8 | F20: PASS | G20: 9.4 | H20: Warning | J20: Replacement pending | K20: 8.1 | N20: 8.2 | R20: 2.8 | S20: Pass | T20: 3.1 | U20: Pass | V20: 3.1 | W20: Pass | X20: 3.2 | Y20: Pass | Z20: 3.2 | AA20: Pass | AB20: 3.3 | AC20: Pass | AD20: 3 | AE20: Pass | AF20: 3.57 | AG20: Pass | AH20: 3.19 | AI20: Pass | AJ20: 3.15 | AK20: Pass | AL20: 3.35 | AM20: Pass | AN20: 3.39 | AO20: Pass | AP20: 3.3 | AQ20: Pass
A21: 18 | B21: 3.7 | C21: 10.9 | D21: 9.2 | E21: 8.5 | F21: PASS | G21: 3.4 | H21: Pass | K21: 9 | N21: 3.1 | R21: 3 | S21: Pass | T21: 2.8 | U21: Pass | V21: 3.6 | W21: Pass | X21: 2.9 | Y21: Pass | Z21: 3.3 | AA21: Pass | AB21: 3.2 | AC21: Pass | AD21: 3.3 | AE21: Pass | AF21: 3.56 | AG21: Pass | AH21: 2.86 | AI21: Pass | AJ21: 3.14 | AK21: Pass | AL21: 3.34 | AM21: Pass | AN21: 3.3 | AO21: Pass | AP21: 3.9 | AQ21: Pass
A22: 19 | B22: 6.1 | C22: 6.8 | D22: 8.7 | E22: 8 | F22: PASS | G22: 2.9 | H22: Pass | K22: 9999 | N22: 3.2 | R22: 3.3 | S22: Pass | T22: 3.4 | U22: Pass | V22: 2.9 | W22: Pass | X22: 3.7 | Y22: Pass | Z22: 2.9 | AA22: Pass | AB22: 3 | AC22: Pass | AD22: 2.7 | AE22: Pass | AF22: 3.34 | AG22: Pass | AH22: 3.16 | AI22: Pass | AJ22: 3.12 | AK22: Pass | AL22: 3.23 | AM22: Pass | AN22: 3.29 | AO22: Pass | AP22: 3.7 | AQ22: Pass
A23: 20 | B23: 6.5 | C23: 9.3 | D23: 3.1 | E23: 3.2 | F23: PASS | G23: 3.2 | H23: Pass | K23: 9999 | N23: 3 | R23: 3.3 | S23: Pass | T23: 3.3 | U23: Pass | V23: 3.1 | W23: Pass | X23: 3.2 | Y23: Pass | Z23: 2.8 | AA23: Pass | AB23: 2.9 | AC23: Pass | AD23: 3.3 | AE23: Pass | AF23: 3.07 | AG23: Pass | AH23: 2.7 | AI23: Pass | AJ23: 3.16 | AK23: Pass | AL23: 3.19 | AM23: Pass | AN23: 3.37 | AO23: Pass | AP23: 3.9 | AQ23: Pass
A24: 21 | B24: 7.7 | C24: 7.3 | D24: 7.1 | E24: 3.3 | F24: PASS | G24: 2.7 | H24: Pass | K24: 13.6 | N24: 3.1 | R24: 3.8 | S24: Pass | T24: 2.9 | U24: Pass | V24: 3.4 | W24: Pass | X24: 4 | Y24: Pass | Z24: 3.7 | AA24: Pass | AB24: 3.3 | AC24: Pass | AD24: 3.2 | AE24: Pass | AF24: 2.96 | AG24: Pass | AH24: 2.97 | AI24: Pass | AJ24: 3.48 | AK24: Pass | AL24: 3.39 | AM24: Pass | AN24: 3.49 | AO24: Pass | AP24: 3.4 | AQ24: Pass
A25: 22 | B25: 6.1 | C25: 7.7 | D25: 6.7 | E25: 9.6 | F25: WARNING | G25: 9.6 | H25: Warning | I25: 2.6 | J25: Replaced with new one | K25: 18.2 | N25: 8.4 | R25: 3.3 | S25: Pass | T25: 3.1 | U25: Pass | V25: 2.6 | W25: Pass | X25: 2.8 | Y25: Pass | Z25: 3 | AA25: Pass | AB25: 3.1 | AC25: Pass | AD25: 2.4 | AE25: Pass | AF25: 3.43 | AG25: Pass | AH25: 3.42 | AI25: Pass | AJ25: 3.14 | AK25: Pass | AL25: 3.26 | AM25: Pass | AN25: 3.34 | AO25: Pass | AP25: 2.8 | AQ25: Pass
A26: 23 | B26: 6.4 | C26: 2.6 | D26: 9.6 | E26: 8.5 | F26: PASS | G26: 7.5 | H26: Pass | K26: 19.8 | N26: 3.4 | R26: 2.9 | S26: Pass | T26: 3.1 | U26: Pass | V26: 2.4 | W26: Pass | X26: 3 | Y26: Pass | Z26: 3 | AA26: Pass | AB26: 3.4 | AC26: Pass | AD26: 2.8 | AE26: Pass | AF26: 3.39 | AG26: Pass | AH26: 3.42 | AI26: Pass | AJ26: 3.21 | AK26: Pass | AL26: 3.36 | AM26: Pass | AN26: 3.44 | AO26: Pass | AP26: 3.4 | AQ26: Pass
A27: 24 | B27: 2.8 | C27: 5.8 | D27: 3.1 | E27: 6.3 | F27: PASS | G27: 8.2 | H27: Pass | K27: 2.6 | N27: 8.9 | R27: 3.5 | S27: Pass | T27: 3.4 | U27: Pass | V27: 2.9 | W27: Pass | X27: 3.1 | Y27: Pass | Z27: 3.4 | AA27: Pass | AB27: 3.5 | AC27: Pass | AD27: 2.8 | AE27: Pass | AF27: 3.5 | AG27: Pass | AH27: 4 | AI27: Pass | AJ27: 3.44 | AK27: Pass | AL27: 3.55 | AM27: Pass | AN27: 3.68 | AO27: Pass | AP27: 3.1 | AQ27: Pass
A28: 25 | B28: 5.2 | C28: 6.4 | D28: 2.9 | E28: 7.6 | F28: PASS | G28: 11.5 | H28: Warning | I28: 2.6 | J28: Replaced with new one | K28: 2.5 | N28: 10.7 | O28: Warning | R28: 3 | S28: Pass | T28: 3 | U28: Pass | V28: 2.1 | W28: Pass | X28: 2.9 | Y28: Pass | Z28: 3 | AA28: Pass | AB28: 3.4 | AC28: Pass | AD28: 2.4 | AE28: Pass | AF28: 3.18 | AG28: Pass | AH28: 3.21 | AI28: Pass | AJ28: 3.5 | AK28: Pass | AL28: 3.46 | AM28: Pass | AN28: 3.55 | AO28: Pass | AP28: 2.9 | AQ28: Pass
A29: 26 | B29: 5.5 | C29: 7.9 | D29: 8.6 | E29: 7 | F29: PASS | G29: 9.3 | H29: Warning | J29: Replacement pending | L29: Battery Reading did not come | N29: 10 | O29: Warning | R29: 2.9 | S29: Pass | T29: 3.2 | U29: Pass | V29: 3.3 | W29: Pass | X29: 3.6 | Y29: Pass | Z29: 2.9 | AA29: Pass | AB29: 3.3 | AC29: Pass | AD29: 2.5 | AE29: Pass | AF29: 3.36 | AG29: Pass | AH29: 3.05 | AI29: Pass | AJ29: 3.18 | AK29: Pass | AL29: 3.39 | AM29: Pass | AN29: 3.46 | AO29: Pass | AP29: 4.1 | AQ29: Pass
A30: 27 | B30: 6.7 | C30: 8.1 | D30: 8.3 | E30: 7.7 | F30: PASS | G30: 7 | H30: Pass | L30: Battery Reading did not come | N30: 8.4 | R30: 3 | S30: Pass | T30: 3.2 | U30: Pass | V30: 3.2 | W30: Pass | X30: 2.9 | Y30: Pass | Z30: 3 | AA30: Pass | AB30: 3.2 | AC30: Pass | AD30: 3.1 | AE30: Pass | AF30: 3.69 | AG30: Pass | AH30: 3.07 | AI30: Pass | AJ30: 3.22 | AK30: Pass | AL30: 3.33 | AM30: Pass | AN30: 3.46 | AO30: Pass | AP30: 3.4 | AQ30: Pass
A31: 28 | B31: 7 | C31: 10 | D31: 8.9 | E31: 2.5 | F31: PASS | G31: 5.8 | H31: Pass | L31: Battery Reading did not come | N31: 3.8 | R31: 3.2 | S31: Pass | T31: 3.1 | U31: Pass | V31: 3.1 | W31: Pass | X31: 2.4 | Y31: Pass | Z31: 3.1 | AA31: Pass | AB31: 3.3 | AC31: Pass | AD31: 2.8 | AE31: Pass | AF31: 3.44 | AG31: Pass | AH31: 3 | AI31: Pass | AJ31: 3.42 | AK31: Pass | AL31: 3.23 | AM31: Pass | AN31: 3.69 | AO31: Pass | AP31: 3.1 | AQ31: Pass
A32: 29 | B32: 8.4 | C32: 6.7 | D32: 8.5 | E32: 6.1 | F32: PASS | G32: 3 | H32: Pass | L32: Battery Reading did not come | N32: 3.7 | R32: 2.9 | S32: Pass | T32: 3.3 | U32: Pass | V32: 3 | W32: Pass | X32: 3.1 | Y32: Pass | Z32: 3.4 | AA32: Pass | AB32: 2.9 | AC32: Pass | AD32: 2.5 | AE32: Pass | AF32: 3.31 | AG32: Pass | AH32: 2.99 | AI32: Pass | AJ32: 3.37 | AK32: Pass | AL32: 3.49 | AM32: Pass | AN32: 3.56 | AO32: Pass | AP32: 3.5 | AQ32: Pass
A33: 30 | B33: 7.7 | C33: 8.2 | D33: 8.8 | E33: 6.6 | F33: PASS | G33: 8.5 | H33: Pass | L33: Battery Reading did not come | N33: 13.3 | O33: Fail | R33: 3 | S33: Pass | T33: 3.5 | U33: Pass | V33: 3 | W33: Pass | X33: 3 | Y33: Pass | Z33: 3.5 | AA33: Pass | AB33: 3 | AC33: Pass | AD33: 3.9 | AE33: Pass | AF33: 2.86 | AG33: Pass | AH33: 3.03 | AI33: Pass | AJ33: 3.19 | AK33: Pass | AL33: 3.28 | AM33: Pass | AN33: 3.51 | AO33: Pass | AP33: 3.6 | AQ33: Pass
A34: 31 | B34: 6.2 | C34: 2.8 | D34: 7.2 | E34: 8.7 | F34: PASS | G34: 6.8 | H34: Pass | L34: Battery Reading did not come | N34: 11.1 | O34: Warning | R34: 3.3 | S34: Pass | T34: 3.2 | U34: Pass | V34: 2.9 | W34: Pass | X34: 3.3 | Y34: Pass | Z34: 3.6 | AA34: Pass | AB34: 3.1 | AC34: Pass | AD34: 3.6 | AE34: Pass | AF34: 3.45 | AG34: Pass | AH34: 3.33 | AI34: Pass | AJ34: 3.13 | AK34: Pass | AL34: 3.3 | AM34: Pass | AN34: 3.18 | AO34: Pass | AP34: 2.9 | AQ34: Pass
A35: 32 | B35: 3 | C35: 6.1 | D35: 6.8 | E35: 9.3 | F35: WARNING | G35: 3.3 | H35: Pass | L35: Battery Reading did not come | N35: 4 | R35: 3 | S35: Pass | T35: 3.8 | U35: Pass | V35: 2.9 | W35: Pass | X35: 2.4 | Y35: Pass | Z35: 3.3 | AA35: Pass | AB35: 3.1 | AC35: Pass | AD35: 2.6 | AE35: Pass | AF35: 3.58 | AG35: Pass | AH35: 2.95 | AI35: Pass | AJ35: 3.15 | AK35: Pass | AL35: 3.33 | AM35: Pass | AN35: 3.49 | AO35: Pass | AP35: 2 | AQ35: Pass
A36: 33 | B36: 7.9 | C36: 5.5 | D36: Made one bank of only 32 good batteries | H36: Disconnected - Gone Bad Last Year | P36: 2.6 | Q36: New Battery Installation done today | R36: 3.4 | S36: Pass | T36: 3.6 | U36: Pass | V36: 3 | W36: Pass | X36: 2.2 | Y36: Pass | Z36: 3.2 | AA36: Pass | AB36: 3.4 | AC36: Pass | AD36: 2.9 | AE36: Pass | AF36: 2.6 | AG36: Pass | AH36: 3.33 | AI36: Pass | AJ36: 3.32 | AK36: Pass | AL36: 3.35 | AM36: Pass | AN36: 3.64 | AO36: Pass | AP36: 3.7 | AQ36: Pass
A37: 34 | B37: 5.3 | C37: 8 | H37: Disconnected - Gone Bad Last Year | P37: 2.7 | Q37: New Battery Installation done today | R37: 3.1 | S37: Pass | T37: 3 | U37: Pass | V37: 3.1 | W37: Pass | X37: 3.3 | Y37: Pass | Z37: 3.2 | AA37: Pass | AB37: 3.2 | AC37: Pass | AD37: 3.5 | AE37: Pass | AF37: 3.33 | AG37: Pass | AH37: 3.35 | AI37: Pass | AJ37: 3.29 | AK37: Pass | AL37: 3.39 | AM37: Pass | AN37: 3.49 | AO37: Pass | AP37: 2.8 | AQ37: Pass
A38: 35 | B38: 7.9 | C38: 7 | H38: Disconnected - Gone Bad Last Year | P38: 2.7 | Q38: New Battery Installation done today | R38: 3.6 | S38: Pass | T38: 3.4 | U38: Pass | V38: 3.4 | W38: Pass | X38: 3.2 | Y38: Pass | Z38: 3.2 | AA38: Pass | AB38: 3.6 | AC38: Pass | AD38: 3.4 | AE38: Pass | AF38: 3.28 | AG38: Pass | AH38: 3.27 | AI38: Pass | AJ38: 3.61 | AK38: Pass | AL38: 3.7 | AM38: Pass | AN38: 3.83 | AO38: Pass | AP38: 3 | AQ38: Pass
A39: 36 | B39: 6.1 | C39: 11.8 | H39: Disconnected - Gone Bad Last Year | P39: 2.6 | Q39: New Battery Installation done today | R39: 3 | S39: Pass | T39: 3.6 | U39: Pass | V39: 3.8 | W39: Pass | X39: 6 | Y39: Pass | Z39: 3.2 | AA39: Pass | AB39: 3.3 | AC39: Pass | AD39: 3.3 | AE39: Pass | AF39: 6.74 | AG39: Pass | AH39: 6.47 | AI39: Pass | AJ39: 3.44 | AK39: Pass | AL39: 3.47 | AM39: Pass | AN39: 3.64 | AO39: Pass | AP39: 3.1 | AQ39: Pass
A40: 37 | B40: 6.6 | C40: 9.4 | H40: Disconnected - Gone Bad Last Year | P40: 2.6 | Q40: New Battery Installation done today | R40: 3.6 | S40: Pass | T40: 3.2 | U40: Pass | V40: 3.7 | W40: Pass | X40: 2.4 | Y40: Pass | Z40: 2.9 | AA40: Pass | AB40: 3 | AC40: Pass | AD40: 3.5 | AE40: Pass | AF40: 4.44 | AG40: Pass | AH40: 3.48 | AI40: Pass | AJ40: 3.6 | AK40: Pass | AL40: 3.54 | AM40: Pass | AN40: 3.89 | AO40: Pass | AP40: 3.4 | AQ40: Pass
...

Sheet MICRO 1 & 2 
A1: Battery Spec: 12 Volts 120 AH
A2: Brand: Exide Powersafe
A3: Sr. No. | B3: 42937 | C3: 17/11/2017 | D3: 23/1/2018 | E3: Comments | F3: 43166 | G3: Comments | H3: 24/10/2018 | I3: Comments - 24/10/2018 | J3: 21/1/2019 | K3: Comments - 21/1/2019 | L3: 19/8/2019 | M3: Comments - 19/8/2019 | N3: 27/9/2019 | O3: Comments - 27/9/2019 | P3: 31/10/2019 | Q3: Comments - 31/10/2019 | R3: 26/11/2019 | S3: Comments - 26/11/2019 | T3: 44044 | U3: Comments - 8/1/2020 | V3: 14/2/2020 | W3: Comments - 14/2/2020 | X3: 44024 | Y3: Comments - 7/12/2020 | Z3: 28/1/2021 | AA3: Comments - 28/1/2021 | AB3: 29/1/2021 | AC3: 17/2/2021 | AD3: Comments - 17/2/2021 | AE3: 44442 | AF3: Comments - 9/3/2021
A4: 1 | B4: 5.8 | C4: 6.5 | D4: 6.3 | E4: PASS | F4: 7.1 | G4: Pass | H4: 8.1 | I4: Pass | J4: 8.6 | K4: Pass | L4: 6.3 | M4: Pass | N4: 8 | O4: Pass | P4: 3.6 | R4: 70.2 | S4: Fail | T4: 6.86 | U4: Pass | V4: 7.4 | W4: Pass | X4: 5.47 | Y4: Pass | AB4: Changed | AC4: 4.37 | AD4: Pass | AE4: 3.9 | AF4: Pass
A5: 2 | B5: 6.2 | C5: 5.7 | D5: 6 | E5: PASS | F5: 7.4 | G5: Pass | H5: 8.7 | I5: Pass | J5: 9.1 | K5: Warning | L5: 6.3 | M5: Pass | N5: 51.6 | O5: Fail | P5: 4.5 | R5: 3.9 | S5: Pass | T5: 5.13 | U5: Pass | V5: 9999 | W5: Fail | X5: 4.56 | Y5: Pass | AB5: Changed | AC5: 3.91 | AD5: Pass | AE5: 3.9 | AF5: Pass
A6: 3 | B6: 5.5 | C6: 5.9 | D6: 5.8 | E6: PASS | F6: 7.3 | G6: Pass | H6: 8.2 | I6: Pass | J6: 8.4 | K6: Pass | L6: 5 | M6: Pass | N6: 8.3 | O6: Pass | P6: 9.9 | Q6: Warning | R6: 53.7 | S6: Fail | T6: 16.21 | U6: Fail | V6: 26.9 | W6: Fail | X6: 4.19 | Y6: Pass | AB6: Changed | AC6: 3.88 | AD6: Pass | AE6: 3.9 | AF6: Pass
A7: 4 | B7: 6 | C7: 5.5 | D7: 6 | E7: PASS | F7: 7.2 | G7: Pass | H7: 7.9 | I7: Pass | J7: 8.5 | K7: Pass | L7: 4.4 | M7: Pass | N7: 21.2 | O7: Fail | P7: 11.6 | Q7: Warning | R7: 3.9 | S7: Pass | U7: No Reading Came | V7: 9999 | W7: Fail | X7: 5.3 | Y7: Pass | AB7: Changed | AC7: 4.04 | AD7: Pass | AE7: 3.66 | AF7: Pass
A8: 5 | B8: 5.6 | C8: 5.1 | D8: 6.3 | E8: PASS | F8: 7.2 | G8: Pass | H8: 7.9 | I8: Pass | J8: 8.2 | K8: Pass | L8: 4.1 | M8: Pass | N8: 5.4 | P8: 4 | R8: 6 | S8: Pass | T8: 7.46 | U8: Pass | V8: 5.14 | W8: Pass | X8: 4.16 | Y8: Pass | AB8: Changed | AC8: 4.23 | AD8: Pass | AE8: 4.21 | AF8: Pass
A9: 6 | B9: 6.4 | C9: 5.7 | D9: 6.3 | E9: PASS | F9: 7.9 | G9: Pass | H9: 8.9 | I9: Pass | J9: 9.6 | K9: Warning | L9: 4.5 | M9: Pass | N9: 7.8 | P9: 4.4 | R9: 4 | S9: Pass | T9: 4.1 | U9: Pass | V9: 5.21 | W9: Pass | X9: 11.63 | Y9: Warning | AB9: Changed | AC9: 4.06 | AD9: Pass | AE9: 4.32 | AF9: Pass
A10: 7 | B10: 5.4 | C10: 5.1 | D10: 5.4 | E10: PASS | F10: 6.8 | G10: Pass | H10: 7.7 | I10: Pass | J10: 7.5 | K10: Pass | L10: 3.9 | M10: Pass | N10: 5 | P10: 5.8 | R10: 3.7 | S10: Pass | T10: 3.92 | U10: Pass | V10: 4.81 | W10: Pass | X10: 5.11 | Y10: Pass | AB10: Changed | AC10: 5.64 | AD10: Pass | AE10: 5.04 | AF10: Pass
A11: 8 | B11: 6 | C11: 5.8 | D11: 6.4 | E11: PASS | F11: 8.5 | G11: Pass | H11: 9.5 | I11: Warning | J11: 10.6 | K11: Warning | L11: 5.1 | M11: Pass | N11: 4.2 | P11: 6.7 | R11: 4.1 | S11: Pass | T11: 6.09 | U11: Pass | V11: 5.97 | W11: Pass | X11: 4.09 | Y11: Pass | AB11: Changed | AC11: 4.75 | AD11: Pass | AE11: 4.8 | AF11: Pass
A12: 9 | B12: 6.1 | C12: 6.2 | D12: 6.9 | E12: PASS | F12: 8.6 | G12: Pass | H12: 9.8 | I12: Warning | J12: 10.5 | K12: Warning | L12: 4.3 | M12: Pass | N12: 4.1 | P12: 3.9 | R12: 3.6 | S12: Pass | T12: 3.93 | U12: Pass | V12: 9999 | W12: Fail | X12: 4.62 | Y12: Pass | AB12: Changed | AC12: 4.91 | AD12: Pass | AE12: 4.28 | AF12: Pass
A13: 10 | B13: 6.3 | C13: 5.6 | D13: 5.9 | E13: PASS | F13: 7.8 | G13: Pass | H13: 8.9 | I13: Pass | J13: 9.2 | K13: Warning | L13: 4.9 | M13: Pass | N13: 4.5 | P13: 3.9 | R13: 4 | S13: Pass | U13: No Reading Came | V13: 4.05 | W13: Pass | X13: 4.05 | Y13: Pass | AB13: Changed | AC13: 4.18 | AD13: Pass | AE13: 3.87 | AF13: Pass
A14: 11 | B14: 5.6 | C14: 6 | D14: 6.6 | E14: PASS | F14: 8.2 | G14: Pass | H14: 9.8 | I14: Pass | J14: 10.4 | K14: Warning | L14: 11.4 | M14: Warning | N14: 49.7 | O14: Fail | P14: 4.2 | R14: 69 | S14: Fail | U14: No Reading Came | V14: 4.16 | W14: Pass | X14: 4.17 | Y14: Pass | AB14: Changed | AC14: 4.37 | AD14: Pass | AE14: 3.88 | AF14: Pass
A15: 12 | B15: 5.8 | C15: 5.4 | D15: 5.9 | E15: PASS | F15: 7.4 | G15: Pass | H15: 7.9 | I15: Pass | J15: 8.5 | K15: Pass | L15: 5.4 | M15: Pass | N15: 5.8 | P15: 4.3 | R15: 6.8 | S15: Pass | T15: 4.21 | U15: Pass | V15: 9999 | W15: Fail | X15: 9999 | Y15: Fail | AB15: Changed | AC15: 3.97 | AD15: Pass | AE15: 3.88 | AF15: Pass
A16: 13 | B16: 5.5 | C16: 5.4 | D16: 5.7 | E16: PASS | F16: 7 | G16: Pass | H16: 7.9 | I16: Pass | J16: 8 | K16: Pass | L16: 4.4 | M16: Pass | N16: 7 | P16: 7.2 | R16: 7.7 | S16: Pass | T16: 4.04 | U16: Pass | V16: 4.09 | W16: Pass | X16: 4.79 | Y16: Pass | AB16: Changed | AC16: 4.61 | AD16: Pass | AE16: 4.29 | AF16: Pass
A17: 14 | B17: 5.6 | C17: 5 | D17: 5.7 | E17: PASS | F17: 6.7 | G17: Pass | H17: 8.8 | I17: Pass | J17: 7.4 | K17: Pass | L17: 4.9 | M17: Pass | N17: 4.1 | P17: 4.9 | R17: 3.9 | S17: Pass | T17: 4.16 | U17: Pass | V17: 3.99 | W17: Pass | X17: 28.97 | Y17: Fail | AB17: Changed | AC17: 3.93 | AD17: Pass | AE17: 3.76 | AF17: Pass
A18: 15 | B18: 5.7 | C18: 5.6 | D18: 6 | E18: PASS | F18: 7.8 | G18: Pass | H18: 7.9 | I18: Pass | J18: 9.1 | K18: Warning | L18: 5 | M18: Pass | N18: 5.7 | P18: 5.8 | R18: 5.6 | S18: Pass | T18: 3.97 | U18: Pass | V18: 9999 | W18: Fail | X18: 9.24 | Y18: Warning | AB18: Changed | AC18: 4.03 | AD18: Pass | AE18: 3.85 | AF18: Pass
A19: 16 | B19: 6.1 | C19: 5.2 | D19: 5.6 | E19: PASS | F19: 6.8 | G19: Pass | H19: 7.6 | I19: Pass | J19: 8.9 | K19: Pass | L19: 3.9 | M19: Pass | N19: 5.8 | P19: 4.9 | R19: 3.9 | S19: Pass | T19: 4.04 | U19: Pass | V19: 5.15 | W19: Pass | X19: 5.25 | Y19: Pass | AB19: Changed | AC19: 3.82 | AD19: Pass | AE19: 3.82 | AF19: Pass
A20: 17 | B20: 5.9 | C20: 5.3 | D20: 5.6 | E20: PASS | F20: 6.5 | G20: Pass | H20: 7.5 | I20: Pass | J20: 8.2 | K20: Pass | L20: 4.8 | M20: Pass | N20: 4 | P20: 6.3 | R20: 4 | S20: Pass | T20: 4.04 | U20: Pass | V20: 9999 | W20: Fail | X20: 5.55 | Y20: Pass | AB20: Changed | AC20: 3.93 | AD20: Pass | AE20: 3.93 | AF20: Pass
A21: 18 | B21: 5.9 | C21: 5.3 | D21: 5.7 | E21: PASS | F21: 6.8 | G21: Pass | H21: 9.2 | I21: Warning | J21: 7.9 | K21: Pass | L21: 4.5 | M21: Pass | N21: 3.9 | P21: 10.6 | Q21: Warning | R21: 4.1 | S21: Pass | T21: 4 | U21: Pass | V21: 9999 | W21: Fail | X21: 7.3 | Y21: Pass | AB21: Changed | AC21: 3.78 | AD21: Pass | AE21: 3.81 | AF21: Pass
A22: 19 | B22: 5.7 | C22: 5.9 | D22: 6.4 | E22: PASS | F22: 7.7 | G22: Pass | H22: 9.5 | I22: Warning | J22: 10.3 | K22: Warning | L22: 5 | M22: Pass | N22: 4 | P22: 6.1 | R22: 5.9 | S22: Pass | T22: 4.09 | U22: Pass | V22: 17.16 | W22: Fail | X22: 4.22 | Y22: Pass | AB22: Changed | AC22: 4.17 | AD22: Pass | AE22: 4.1 | AF22: Pass
A23: 20 | B23: 5.4 | C23: 5.7 | D23: 6.7 | E23: PASS | F23: 7.9 | G23: Pass | H23: 9.9 | I23: Warning | J23: 10.3 | K23: Warning | L23: 4 | M23: Pass | N23: 3.9 | P23: 6.2 | R23: 4.1 | S23: Pass | T23: 3.98 | U23: Pass | V23: 16.81 | W23: Fail | X23: 4.12 | Y23: Pass | AB23: Changed | AC23: 3.89 | AD23: Pass | AE23: 3.75 | AF23: Pass
A24: 21 | B24: 5.7 | C24: 5.9 | D24: 6.5 | E24: PASS | F24: 7.9 | G24: Pass | H24: 9.3 | I24: Warning | J24: 10 | K24: Warning | L24: 4.1 | M24: Pass | N24: 4.1 | P24: 4.8 | R24: 4.5 | S24: Pass | T24: 4.18 | U24: Pass | V24: 9999 | W24: Fail | X24: 4.16 | Y24: Pass | AB24: Changed | AC24: 3.83 | AD24: Pass | AE24: 3.86 | AF24: Pass
A25: 22 | B25: 5.7 | C25: 6.2 | D25: 6.7 | E25: PASS | F25: 8.1 | G25: Pass | H25: 9.9 | I25: Warning | J25: 10.9 | K25: Warning | L25: 4.2 | M25: Pass | N25: 4.1 | P25: 14.9 | Q25: Fail | R25: 32 | S25: Fail | T25: 4.21 | U25: Pass | V25: 5.26 | W25: Pass | X25: 4.07 | Y25: Pass | AB25: Changed | AC25: 3.83 | AD25: Pass | AE25: 3.83 | AF25: Pass
A26: 23 | B26: 5.7 | C26: 5.6 | D26: 6 | E26: PASS | F26: 7.1 | G26: Pass | H26: 8.4 | I26: Pass | J26: 9.3 | K26: Warning | L26: 4.4 | M26: Pass | N26: 4.1 | P26: 4 | R26: 4.6 | S26: Pass | T26: 4.08 | U26: Pass | V26: 21.94 | W26: Fail | X26: 9999 | Y26: Fail | AB26: Changed | AC26: 3.73 | AD26: Pass | AE26: 3.72 | AF26: Pass
A27: 24 | B27: 5.6 | C27: 5.4 | D27: 6.4 | E27: PASS | F27: 7.2 | G27: Pass | H27: 8.4 | I27: Pass | J27: 9.1 | K27: Warning | L27: 5.6 | M27: Pass | N27: 4.3 | P27: 4.3 | R27: 5.2 | S27: Pass | T27: 4.38 | U27: Pass | V27: 6.85 | W27: Pass | X27: 6.3 | Y27: Pass | AB27: Changed | AC27: 7.3 | AD27: Pass | AE27: 7.06 | AF27: Pass
A28: 25 | B28: 5.7 | C28: 6.2 | D28: 6.6 | E28: PASS | F28: 8.3 | G28: Pass | H28: 8.9 | I28: Pass | J28: 9.8 | K28: Warning | L28: 5.1 | M28: Pass | N28: 4.2 | P28: 4.3 | R28: 5.8 | S28: Pass | T28: 4.22 | U28: Pass | V28: 24.44 | W28: Fail | X28: 4.52 | Y28: Pass | AB28: Changed | AC28: 3.65 | AD28: Pass | AE28: 3.63 | AF28: Pass
A29: 26 | B29: 5.7 | C29: 5.6 | D29: 6 | E29: PASS | F29: 7.8 | G29: Pass | H29: 8.4 | I29: Pass | J29: 9.1 | K29: Warning | L29: 4.1 | M29: Pass | N29: 4 | P29: 5.4 | R29: 4 | S29: Pass | T29: 4.08 | U29: Pass | V29: 5.66 | W29: Pass | X29: 4.56 | Y29: Pass | AB29: Changed | AC29: 3.79 | AD29: Pass | AE29: 3.85 | AF29: Pass
A30: 27 | B30: 5.8 | C30: 5.7 | D30: 6.2 | E30: PASS | F30: 7.6 | G30: Pass | H30: 8.5 | I30: Pass | J30: 9 | K30: Warning | L30: 4.5 | M30: Pass | N30: 4.4 | P30: 5.8 | R30: 4 | S30: Pass | T30: 4.02 | U30: Pass | V30: 6.08 | W30: Pass | X30: 4 | Y30: Pass | AB30: Changed | AC30: 3.84 | AD30: Pass | AE30: 3.84 | AF30: Pass
A31: 28 | B31: 5.9 | C31: 6 | D31: 6.5 | E31: PASS | F31: 8.7 | G31: Pass | H31: 9.5 | I31: Warning | J31: 10.6 | K31: Warning | L31: 3.9 | M31: Pass | N31: 4 | P31: 6.6 | R31: 4 | S31: Pass | T31: 5.84 | U31: Pass | V31: 5.45 | W31: Pass | X31: 4.13 | Y31: Pass | AB31: Changed | AC31: 3.74 | AD31: Pass | AE31: 3.8 | AF31: Pass
A32: 29 | B32: 5.6 | C32: 6 | D32: 6.5 | E32: PASS | F32: 8.4 | G32: Pass | H32: 9.2 | I32: Warning | J32: 10.2 | K32: Warning | L32: 4.1 | M32: Pass | N32: 4.1 | P32: 5.3 | R32: 4.1 | S32: Pass | T32: 4.13 | U32: Pass | V32: 6.12 | W32: Pass | X32: 4.13 | Y32: Pass | AB32: Changed | AC32: 3.74 | AD32: Pass | AE32: 3.65 | AF32: Pass
A33: 30 | B33: 6 | C33: 6.7 | D33: 6.4 | E33: PASS | F33: 8.5 | G33: Pass | H33: 10 | I33: Warning | J33: 11 | K33: Warning | L33: 5 | M33: Pass | N33: 4.6 | P33: 5.1 | R33: 4.2 | S33: Pass | T33: 4.18 | U33: Pass | V33: 6.91 | W33: Pass | X33: 4.04 | Y33: Pass | AB33: Changed | AC33: 4.01 | AD33: Pass | AE33: 3.8 | AF33: Pass
A34: 31 | B34: 5.3 | C34: 6 | D34: 6.9 | E34: PASS | F34: 8.2 | G34: Pass | H34: 9.9 | I34: Warning | J34: 10.7 | K34: Warning | L34: 10.6 | M34: Warning | N34: 3.9 | P34: 4.7 | R34: 11 | S34: Warning | T34: 3.93 | U34: Pass | V34: 5.29 | W34: Pass | X34: 4.09 | Y34: Pass | AB34: Changed | AC34: 3.76 | AD34: Pass | AE34: 3.75 | AF34: Pass
A35: 32 | B35: 5.7 | C35: 5.5 | D35: 5.9 | E35: PASS | F35: 7 | G35: Pass | H35: 8.4 | I35: Pass | J35: 8.6 | K35: Pass | L35: 5.4 | M35: Pass | N35: 3.9 | P35: 8.6 | R35: 3.9 | S35: Pass | T35: 4.02 | U35: Pass | V35: 9999 | W35: Fail | X35: 4.41 | Y35: Pass | AB35: Changed | AC35: 4.34 | AD35: Pass | AE35: 3.75 | AF35: Pass
A36: 33 | B36: 5.4 | C36: 7 | D36: 7.9 | E36: PASS | F36: 9.8 | G36: Warning | H36: 12 | I36: Failed | J36: 12.8 | K36: Failed | L36: 5 | M36: Pass | N36: 4 | P36: 4.1 | R36: 4.4 | S36: Pass | T36: 4.1 | U36: Pass | V36: 9999 | W36: Fail | X36: 4.29 | Y36: Pass | AB36: Changed | AC36: 4 | AD36: Pass | AE36: 3.65 | AF36: Pass
A37: 34 | B37: 5.8 | C37: 5.4 | D37: 5.9 | E37: PASS | F37: 6.9 | G37: Pass | H37: 8.4 | I37: Pass | J37: 8.4 | K37: Pass | L37: 5 | M37: Pass | N37: 4.1 | P37: 4.9 | R37: 18.8 | S37: Fail | T37: 4.18 | U37: Pass | V37: 5.2 | W37: Pass | X37: 7.67 | Y37: Pass | AB37: Changed | AC37: 4.11 | AD37: Pass | AE37: 3.99 | AF37: Pass
... A54: 51 | B54: 5.5 | C54: 6.3 | D54: 7.1 | E54: PASS | F54: 9.2 | G54: Warning | H54: 11 | I54: Warning | J54: 12.4 | K54: Failed | L54: 5.7 | M54: Pass | N54: 6.5 | P54: 4 | R54: 4.1 | S54: Pass | T54: 4.1 | U54: Pass | V54: 12.24 | W54: Fail | X54: 4.25 | Y54: Pass | AB54: Changed | AC54: 4.07 | AD54: Pass | AE54: 3.6 | AF54: Pass
A55: 52 | B55: 5.8 | C55: 5.7 | D55: 6.3 | E55: PASS | F55: 8 | G55: Pass | H55: 9.6 | I55: Warning | J55: 10.1 | K55: Warning | L55: 5.7 | M55: Pass | N55: 7.3 | P55: 4.4 | R55: 4 | S55: Pass | U55: No Reading Came | V55: 9999 | W55: Fail | X55: 4.16 | Y55: Pass | AB55: Changed | AC55: 4.99 | AD55: Pass | AE55: 3.93 | AF55: Pass
A56: 53 | B56: 5.5 | C56: 6 | D56: 6.6 | E56: PASS | F56: 8.4 | G56: Pass | H56: 10.1 | I56: Warning | J56: 10.7 | K56: Warning | L56: 4 | M56: Pass | N56: 4 | P56: 4.3 | R56: 4 | S56: Pass | T56: 4.08 | U56: Pass | V56: 5.58 | W56: Pass | X56: 6.27 | Y56: Pass | AB56: Changed | AC56: 5.44 | AD56: Pass | AE56: 3.99 | AF56: Pass
...

Sheet MBE 
A1: Battery Spec: 12 Volts 120 AH
A2: Brand:
A3: Brand:
A4: Sr. No. | B4: 42936 | C4: 16/11/2017 | D4: Comments | E4: 43222 | F4: Comments | G4: 43289 | H4: Comments | I4: 24/10/2018 | J4: Comments - 24/10/2018 | K4: 21/1/2019 | L4: Comments - 21/1/2019 | M4: 19/8/2019 | N4: Comments - 19/8/2019 | O4: 27/9/2019 | P4: Comments - 27/9/2019 | Q4: 31/10/2019 | R4: Comments - 31/10/2019 | S4: 27/11/2019 | T4: Comments - 27/11/2019 | U4: 43840 | V4: Comments - 10/1/2020 | W4: 17/2/2020 | X4: Comments - 17/2/2020 | Y4: 44147 | Z4: Comments - 11/12/2020 | AA4: 17/2/2021 | AB4: Comments - 17/2/2021 | AC4: 18/3/2021 | AD4: Comments - 18/3/2021 | AE4: 22/4/2021 | AF4: Comments - 22/4/2021
A5: 1 | B5: 6 | C5: 5.8 | E5: 4.7 | G5: 6 | H5: Pass | I5: 5.1 | J5: Pass | K5: 4.5 | L5: Pass | M5: 5.8 | N5: Pass | O5: 5.5 | P5: Pass | Q5: 5.7 | R5: Pass | S5: 5.8 | T5: Pass | U5: 5.66 | V5: Pass | W5: 5.51 | X5: Pass | Y5: 6.14 | Z5: Pass | AA5: 6.37 | AB5: Pass | AC5: 6.36 | AD5: Pass | AE5: 7.2 | AF5: Pass
A6: 2 | B6: 6.1 | C6: 4.8 | E6: 5 | G6: 5.4 | H6: Pass | I6: 6.6 | J6: Pass | K6: 5.7 | L6: Pass | M6: 6.6 | N6: Pass | O6: 5.5 | P6: Pass | Q6: 6.5 | R6: Pass | S6: 6.3 | T6: Pass | U6: 5.34 | V6: Pass | W6: 6.21 | X6: Pass | Y6: 6.58 | Z6: Pass | AA6: 6.18 | AB6: Pass | AC6: 6.68 | AD6: Pass | AE6: 6.7 | AF6: Pass
A7: 3 | B7: 6.5 | C7: 5.6 | E7: 5.2 | G7: 5.7 | H7: Pass | I7: 5.3 | J7: Pass | K7: 4.9 | L7: Pass | M7: 6 | N7: Pass | O7: 6.4 | P7: Pass | Q7: 6.1 | R7: Pass | S7: 5.5 | T7: Pass | U7: 5.51 | V7: Pass | W7: 5.64 | X7: Pass | Y7: 6.94 | Z7: Pass | AA7: 6.51 | AB7: Pass | AC7: 6.41 | AD7: Pass | AE7: 6.2 | AF7: Pass
A8: 4 | B8: 5.9 | C8: 4.1 | E8: 4.4 | G8: 4.6 | H8: Pass | I8: 5.6 | J8: Pass | K8: 6.2 | L8: Pass | M8: 5.9 | N8: Pass | O8: 5.1 | P8: Pass | Q8: 5.6 | R8: Pass | S8: 6.1 | T8: Pass | U8: 5.83 | V8: Pass | W8: 5.95 | X8: Pass | Y8: 5.94 | Z8: Pass | AA8: 6.37 | AB8: Pass | AC8: 6.7 | AD8: Pass | AE8: 6.2 | AF8: Pass
A9: 5 | B9: 6 | C9: 5.1 | E9: 4.6 | G9: 5.1 | H9: Pass | I9: 4.9 | J9: Pass | K9: 5.4 | L9: Pass | M9: 5.5 | N9: Pass | O9: 5.4 | P9: Pass | Q9: 5.6 | R9: Pass | S9: 5.8 | T9: Pass | U9: 5.74 | V9: Pass | W9: 5.78 | X9: Pass | Y9: 6.09 | Z9: Pass | AA9: 6.43 | AB9: Pass | AC9: 6.89 | AD9: Pass | AE9: 7.5 | AF9: Pass
A10: 6 | B10: 6.1 | C10: 4.2 | E10: 5.9 | G10: 4.6 | H10: Pass | I10: 4.7 | J10: Pass | K10: 6.3 | L10: Pass | M10: 5.7 | N10: Pass | O10: 5.1 | P10: Pass | Q10: 5.2 | R10: Pass | S10: 6.9 | T10: Pass | U10: 6.4 | V10: Pass | W10: 4.92 | X10: Pass | Y10: 5.47 | Z10: Pass | AA10: 6.81 | AB10: Pass | AC10: 5.95 | AD10: Pass | AE10: 6.8 | AF10: Pass
A11: 7 | B11: 5.5 | C11: 6.4 | E11: 4.3 | G11: 4.3 | H11: Pass | I11: 5.3 | J11: Pass | K11: 5.7 | L11: Pass | M11: 5.8 | N11: Pass | O11: 4.9 | P11: Pass | Q11: 5.1 | R11: Pass | S11: 5 | T11: Pass | U11: 5.77 | V11: Pass | W11: 5.63 | X11: Pass | Y11: 6.34 | Z11: Pass | AA11: 6.17 | AB11: Pass | AC11: 6.28 | AD11: Pass | AE11: 6.5 | AF11: Pass
A12: 8 | B12: 6.2 | C12: 4.7 | E12: 6 | G12: 4.5 | H12: Pass | I12: 6.2 | J12: Pass | K12: 5 | L12: Pass | M12: 7.4 | N12: Pass | O12: 6.5 | P12: Pass | Q12: 6.3 | R12: Pass | S12: 5.5 | T12: Pass | U12: 5.31 | V12: Pass | W12: 4.9 | X12: Pass | Y12: 5.86 | Z12: Pass | AA12: 6.35 | AB12: Pass | AC12: 6.22 | AD12: Pass | AE12: 6.7 | AF12: Pass
A13: 9 | B13: 6.3 | C13: 6.4 | E13: 5.9 | G13: 6.6 | H13: Pass | I13: 5.8 | J13: Pass | K13: 6.1 | L13: Pass | M13: 5.2 | N13: Pass | O13: 5.9 | P13: Pass | Q13: 6.2 | R13: Pass | S13: 6.6 | T13: Pass | U13: 5.78 | V13: Pass | W13: 6.15 | X13: Pass | Y13: 6.5 | Z13: Pass | AA13: 6.15 | AB13: Pass | AC13: 6.26 | AD13: Pass | AE13: 7.1 | AF13: Pass
A14: 10 | B14: 6.1 | C14: 6.6 | E14: 4.5 | G14: 4.4 | H14: Pass | I14: 5 | J14: Pass | K14: 5.3 | L14: Pass | M14: 6.9 | N14: Pass | O14: 6.4 | P14: Pass | Q14: 6.6 | R14: Pass | S14: 5.5 | T14: Pass | U14: 5.35 | V14: Pass | W14: 5.59 | X14: Pass | Y14: 5.91 | Z14: Pass | AA14: 6.77 | AB14: Pass | AC14: 6.26 | AD14: Pass | AE14: 6.5 | AF14: Pass
A15: 11 | B15: 6.2 | C15: 4.5 | E15: 4.5 | G15: 4.2 | H15: Pass | I15: 6.1 | J15: Pass | K15: 4.7 | L15: Pass | M15: 7.2 | N15: Pass | O15: 6.2 | P15: Pass | Q15: 7.4 | R15: Pass | S15: 5.6 | T15: Pass | U15: 5.4 | V15: Pass | W15: 5.37 | X15: Pass | Y15: 5.87 | Z15: Pass | AA15: 6.08 | AB15: Pass | AC15: 6.13 | AD15: Pass | AE15: 6.4 | AF15: Pass
A16: 12 | B16: 6.1 | C16: 5.4 | E16: 5.6 | G16: 5 | H16: Pass | I16: 5.6 | J16: Pass | K16: 6.2 | L16: Pass | M16: 5.6 | N16: Pass | O16: 5.7 | P16: Pass | Q16: 5.3 | R16: Pass | S16: 6.4 | T16: Pass | U16: 5.55 | V16: Pass | W16: 5.55 | X16: Pass | Y16: 6.49 | Z16: Pass | AA16: 6.61 | AB16: Pass | AC16: 6.23 | AD16: Pass | AE16: 7.4 | AF16: Pass
... A25: 21 | B25: 6.1 | C25: 4.7 | E25: 4.9 | G25: 5 | H25: Pass | I25: 5.3 | J25: Pass | K25: 5.6 | L25: Pass | M25: 6 | N25: Pass | O25: 6 | P25: Pass | Q25: 5.4 | R25: Pass | S25: 6.2 | T25: Pass | U25: 6.25 | V25: Pass | W25: 5.5 | X25: Pass | Y25: 6.85 | Z25: Pass | AA25: 6.96 | AB25: Pass | AC25: 6.51 | AD25: Pass | AE25: 7.5 | AF25: Pass
A26: 22 | B26: 7 | D26: Reading did not come | F26: Reading did not come | G26: 5.2 | H26: Pass | I26: 5.5 | J26: Pass | K26: 5.6 | L26: Pass | M26: 5.7 | N26: Pass | O26: 5.1 | P26: Pass | Q26: 5.3 | R26: Pass | S26: 5.9 | T26: Pass | U26: 3.9 | V26: Pass | W26: 5.46 | X26: Pass | Y26: 4.88 | Z26: Pass | AA26: 5.04 | AB26: Pass | AC26: 5.23 | AD26: Pass | AE26: 6.1 | AF26: Pass
A27: 23 | B27: 6.2 | C27: 4.7 | E27: 5.1 | G27: 5.3 | H27: Pass | I27: 8.1 | J27: Pass | K27: 5.4 | L27: Pass | M27: 6.3 | N27: Pass | O27: 5.2 | P27: Pass | Q27: 5.3 | R27: Pass | S27: 5.3 | T27: Pass | U27: 5.25 | V27: Pass | W27: 5.91 | X27: Pass | Y27: 5.88 | Z27: Pass | AA27: 6.64 | AB27: Pass | AC27: 6.25 | AD27: Pass | AE27: 6.3 | AF27: Pass
A28: 24 | B28: 6.1 | C28: 5.3 | E28: 4.4 | G28: 4.6 | H28: Pass | I28: 5.3 | J28: Pass | K28: 5.9 | L28: Pass | M28: 6 | N28: Pass | O28: 5.2 | P28: Pass | Q28: 5.6 | R28: Pass | S28: 5.4 | T28: Pass | U28: 5.69 | V28: Pass | W28: 5.71 | X28: Pass | Y28: 5.82 | Z28: Pass | AA28: 6.87 | AB28: Pass | AC28: 6.8 | AD28: Pass | AE28: 6.8 | AF28: Pass
A29: 25 | B29: 6.1 | C29: 4.5 | E29: 4.3 | G29: 4.7 | H29: Pass | I29: 5.7 | J29: Pass | K29: 5.8 | L29: Pass | M29: 5.9 | N29: Pass | O29: 5.3 | P29: Pass | Q29: 5.5 | R29: Pass | S29: 5.5 | T29: Pass | U29: 5.98 | V29: Pass | W29: 5.06 | X29: Pass | Y29: 5.96 | Z29: Pass | AA29: 6.73 | AB29: Pass | AC29: 6.72 | AD29: Pass | AE29: 7.2 | AF29: Pass
A30: 26 | B30: 5.9 | C30: 4.7 | E30: 4.6 | G30: 4.8 | H30: Pass | I30: 5 | J30: Pass | K30: 5.4 | L30: Pass | M30: 5.5 | N30: Pass | O30: 5.1 | P30: Pass | Q30: 5.8 | R30: Pass | S30: 5.1 | T30: Pass | U30: 6.09 | V30: Pass | W30: 5.22 | X30: Pass | Y30: 5.93 | Z30: Pass | AA30: 6.96 | AB30: Pass | AC30: 6.61 | AD30: Pass | AE30: 6.9 | AF30: Pass
A31: 27 | B31: 6 | C31: 4.6 | E31: 4.1 | G31: 4.2 | H31: Pass | I31: 5.4 | J31: Pass | K31: 20.5 | L31: Fail | M31: 5.9 | N31: Pass | O31: 5.3 | P31: Pass | Q31: 5.1 | R31: Pass | S31: 5.4 | T31: Pass | U31: 5.5 | V31: Pass | W31: 5.38 | X31: Pass | Y31: 5.81 | Z31: Pass | AA31: 6.58 | AB31: Pass | AC31: 6.29 | AD31: Pass | AE31: 7 | AF31: Pass
A32: 28 | B32: 6.1 | C32: 4.2 | E32: 4.4 | G32: 4.7 | H32: Pass | I32: 5.2 | J32: Pass | K32: 4.9 | L32: Pass | M32: 5.7 | N32: Pass | O32: 5.6 | P32: Pass | Q32: 5.5 | R32: Pass | S32: 5.2 | T32: Pass | U32: 6.19 | V32: Pass | W32: 5.39 | X32: Pass | Y32: 6.09 | Z32: Pass | AA32: 6.15 | AB32: Pass | AC32: 6.13 | AD32: Pass | AE32: 7.5 | AF32: Pass
A33: 29 | B33: 6.3 | C33: 4.8 | E33: 4.2 | G33: 4.8 | H33: Pass | I33: 5.3 | J33: Pass | K33: 5.2 | L33: Pass | M33: 5.8 | N33: Pass | O33: 5.7 | P33: Pass | Q33: 5.2 | R33: Pass | S33: 5.3 | T33: Pass | U33: 5.25 | V33: Pass | W33: 6.67 | X33: Pass | Y33: 5.75 | Z33: Pass | AA33: 5.97 | AB33: Pass | AC33: 6.06 | AD33: Pass | AE33: 7.5 | AF33: Pass
A34: 30 | B34: 5.5 | C34: 5 | E34: 4.7 | G34: 5.2 | H34: Pass | I34: 5.5 | J34: Pass | K34: 5.1 | L34: Pass | M34: 5.9 | N34: Pass | O34: 5.9 | P34: Pass | Q34: 5.1 | R34: Pass | S34: 5.5 | T34: Pass | U34: 5.3 | V34: Pass | W34: 4.97 | X34: Pass | Y34: 5.81 | Z34: Pass | AA34: 6.56 | AB34: Pass | AC34: 6.05 | AD34: Pass | AE34: 6.1 | AF34: Pass
A35: 31 | B35: 14.2 | C35: 4.6 | D35: Changed in Oct' 17 | E35: 4.5 | G35: 5.5 | H35: Pass | I35: 5.1 | J35: Pass | K35: 4.7 | L35: Pass | M35: 5.5 | N35: Pass | O35: 5.8 | P35: Pass | Q35: 5.4 | R35: Pass | S35: 5.2 | T35: Pass | U35: 5.8 | V35: Pass | W35: 5.87 | X35: Pass | Y35: 6.21 | Z35: Pass | AA35: 6.35 | AB35: Pass | AC35: 5.9 | AD35: Pass | AE35: 6.4 | AF35: Pass
A36: 32 | B36: 6 | C36: 5 | E36: 4.3 | G36: 4.7 | H36: Pass | I36: 5.6 | J36: Pass | K36: 29.1 | L36: Fail | M36: 5.5 | N36: Pass | O36: 6.4 | P36: Pass | Q36: 5.3 | R36: Pass | S36: 5.5 | T36: Pass | U36: 5.38 | V36: Pass | W36: 5.23 | X36: Pass | Y36: 6.23 | Z36: Pass | AA36: 6.88 | AB36: Pass | AC36: 6.41 | AD36: Pass | AE36: 7.3 | AF36: Pass
A37: 33 | B37: 6.3 | C37: 4.3 | E37: 4.3 | G37: 4.7 | H37: Pass | I37: 5.9 | J37: Pass | K37: 5.7 | L37: Pass | M37: 6.1 | N37: Pass | O37: 5.4 | P37: Pass | Q37: 6.1 | R37: Pass | S37: 5.7 | T37: Pass | U37: 6.32 | V37: Pass | W37: 5.56 | X37: Pass | Y37: 5.93 | Z37: Pass | AA37: 6.97 | AB37: Pass | AC37: 6.2 | AD37: Pass | AE37: 7 | AF37: Pass
A38: 34 | B38: 6.1 | C38: 4.6 | E38: 4.3 | G38: 4.7 | H38: Pass | I38: 5.2 | J38: Pass | K38: 5.6 | L38: Pass | M38: 6 | N38: Pass | O38: 5.2 | P38: Pass | Q38: 5.6 | R38: Pass | S38: 5.3 | T38: Pass | U38: 5.91 | V38: Pass | W38: 6.35 | X38: Pass | Y38: 6.54 | Z38: Pass | AA38: 7.06 | AB38: Pass | AC38: 6.91 | AD38: Pass | AE38: 8.4 | AF38: Pass
A39: 35 | B39: 6.1 | C39: 5.3 | E39: 4.3 | G39: 4.5 | H39: Pass | I39: 5.3 | J39: Pass | K39: 6 | L39: Pass | M39: 5.7 | N39: Pass | O39: 5.3 | P39: Pass | Q39: 5.4 | R39: Pass | S39: 5.3 | T39: Pass | U39: 5.6 | V39: Pass | W39: 5.13 | X39: Pass | Y39: 5.76 | Z39: Pass | AA39: 6.1 | AB39: Pass | AC39: 6.43 | AD39: Pass | AE39: 6.7 | AF39: Pass
A40: 36 | B40: 6.3 | C40: 4.3 | E40: 4.3 | G40: 4.7 | H40: Pass | I40: 5.3 | J40: Pass | K40: 5.5 | L40: Pass | M40: 6 | N40: Pass | O40: 5 | P40: Pass | Q40: 5.7 | R40: Pass | S40: 5.2 | T40: Pass | U40: 5.81 | V40: Pass | W40: 4.92 | X40: Pass | Y40: 5.85 | Z40: Pass | AA40: 6.63 | AB40: Pass | AC40: 6.08 | AD40: Pass | AE40: 6.8 | AF40: Pass
A41: 37 | B41: 6.1 | C41: 4.7 | E41: 4.2 | G41: 4.5 | H41: Pass | I41: 5.6 | J41: Pass | K41: 5.5 | L41: Pass | M41: 5.5 | N41: Pass | O41: 5.3 | P41: Pass | Q41: 5.1 | R41: Pass | S41: 5.4 | T41: Pass | U41: 5.49 | V41: Pass | W41: 6.06 | X41: Pass | Y41: 5.62 | Z41: Pass | AA41: 6.13 | AB41: Pass | AC41: 5.7 | AD41: Pass | AE41: 6.4 | AF41: Pass
A42: 38 | B42: 6.2 | C42: 4.4 | E42: 4.4 | G42: 4.7 | H42: Pass | I42: 5.2 | J42: Pass | K42: 4.7 | L42: Pass | M42: 5.9 | N42: Pass | O42: 5.1 | P42: Pass | Q42: 5.5 | R42: Pass | S42: 5.3 | T42: Pass | U42: 5.99 | V42: Pass | W42: 5.47 | X42: Pass | Y42: 5.9 | Z42: Pass | AA42: 6.46 | AB42: Pass | AC42: 6.07 | AD42: Pass | AE42: 6.8 | AF42: Pass
A43: 39 | B43: 5.9 | C43: 4.8 | E43: 4.7 | G43: 5 | H43: Pass | I43: 5.3 | J43: Pass | K43: 5 | L43: Pass | M43: 5.7 | N43: Pass | O43: 5.2 | P43: Pass | Q43: 5.3 | R43: Pass | S43: 5.3 | T43: Pass | U43: 5.34 | V43: Pass | W43: 5.88 | X43: Pass | Y43: 6.52 | Z43: Pass | AA43: 6.18 | AB43: Pass | AC43: 6.25 | AD43: Pass | AE43: 7 | AF43: Pass
A44: 40 | B44: 6.3 | C44: 3.9 | E44: 4.6 | G44: 5.3 | H44: Pass | I44: 4.1 | J44: Pass | K44: 4.4 | L44: Pass | M44: 4.8 | N44: Pass | O44: 4.1 | P44: Pass | Q44: 5.3 | R44: Pass | S44: 4 | T44: Pass | U44: 5.21 | V44: Pass | W44: 5.78 | X44: Pass | Y44: 6.39 | Z44: Pass | AA44: 5.96 | AB44: Pass | AC44: 6.08 | AD44: Pass | AE44: 6.5 | AF44: Pass
A45: 41 | B45: 4.5 | C45: 3.7 | E45: 4.1 | G45: 4.2 | H45: Pass | I45: 4 | J45: Pass | K45: 3.9 | L45: Pass | M45: 4.8 | N45: Pass | O45: 4.7 | P45: Pass | Q45: 4.4 | R45: Pass | S45: 4.1 | T45: Pass | U45: 4.24 | V45: Pass | W45: 6.51 | X45: Pass | Y45: 7.77 | Z45: Pass | AA45: 9.09 | AB45: Warning | AC45: 9.49 | AD45: Warning | AE45: 11 | AF45: Warning
A46: 42 | B46: 4.6 | C46: 3.9 | E46: 3.9 | G46: 4 | H46: Pass | I46: 4.3 | J46: Pass | K46: 3.9 | L46: Pass | M46: 4.6 | N46: Pass | O46: 4.7 | P46: Pass | Q46: 4.5 | R46: Pass | S46: 4.2 | T46: Pass | U46: 4.91 | V46: Pass | W46: 6.03 | X46: Pass | Y46: 9.05 | Z46: Warning | AA46: 10.47 | AB46: Warning | AC46: 10.89 | AD46: Warning | AE46: 12.6 | AF46: Fail
A47: 43 | B47: 4.8 | C47: 3.8 | E47: 4 | G47: 4 | H47: Pass | I47: 4.2 | J47: Pass | K47: 4.1 | L47: Pass | M47: 4.5 | N47: Pass | O47: 4.3 | P47: Pass | Q47: 4.7 | R47: Pass | S47: 4.1 | T47: Pass | U47: 5.11 | V47: Pass | W47: 6.27 | X47: Pass | Y47: 9.7 | Z47: Warning | AA47: 11.43 | AB47: Warning | AC47: 11.52 | AD47: Warning | AE47: 13.8 | AF47: Fail
... A98: 94 | B98: 4.6 | C98: 4.5 | E98: 4.3 | G98: 4 | H98: Pass | I98: 5.6 | J98: Pass | K98: 4.6 | L98: Pass | M98: 4.9 | N98: Pass | O98: 6.1 | P98: Pass | Q98: 6.3 | R98: Pass | S98: 5.6 | T98: Pass | U98: 5.97 | V98: Pass | W98: 6.42 | X98: Pass | Y98: 16.34 | Z98: Fail | AA98: 21.1 | AB98: Fail | AC98: 22.75 | AD98: Fail | AE98: 26.4 | AF98: Fail
...

Sheet NCPRE 
A1: Battery Spec: 12 Volts, 120 AH
A2: Brand:
A3: Brand:
A4: Sr. No. | B4: 42936 | C4: 30/8/2017 | D4: 16/11/2017 | E4: Comments | F4: 43102 | G4: Comments | H4: 43289 | I4: Comments | J4: 21/1/2019 | K4: Comments - 21/1/2019 | L4: 19/8/2019 | M4: Comments - 19/8/2019 | N4: 27/9/2019 | O4: Comments - 27/9/2019 | P4: 31/10/2019 | Q4: Comments - 31/10/2019 | R4: 29/11/2019 | S4: Comments - 29/11/2019 | T4: 44147 | U4: Comments - 11/12/2020 | V4: 17/2/2021 | W4: Comments - 17/2/2021 | X4: 18/3/2021 | Y4: Comments - 18/3/2021 | Z4: 22/4/2021 | AA4: Comments - 22/4/2021
A5: 1 | B5: 4.2 | C5: 4.2 | D5: 5.8 | F5: 4.5 | H5: 4.5 | I5: Pass | J5: 4.4 | K5: Pass | L5: 4.7 | M5: Pass | N5: 5.1 | O5: Pass | P5: 5.9 | R5: 4.6 | S5: Pass | T5: 8.7 | U5: Pass | V5: 5.72 | W5: Pass | X5: 5.43 | Y5: Pass | Z5: 7.1 | AA5: Pass
A6: 2 | B6: 6.5 | C6: 4.4 | D6: 4.8 | F6: 4.6 | H6: 5.4 | I6: Pass | J6: 5.1 | K6: Pass | L6: 5.3 | M6: Pass | N6: 4.3 | O6: Pass | P6: 5.6 | R6: 4.8 | S6: Pass | T6: 7.48 | U6: Pass | V6: 5.9 | W6: Pass | X6: 5.79 | Y6: Pass | Z6: 6 | AA6: Pass
A7: 3 | B7: 5.1 | C7: 4.5 | D7: 5.6 | F7: 4.3 | H7: 4.4 | I7: Pass | J7: 4.8 | K7: Pass | L7: 5.5 | M7: Pass | N7: 4.6 | O7: Pass | P7: 7.2 | R7: 5.5 | S7: Pass | T7: 11.09 | U7: Warning | V7: 6.3 | W7: Pass | X7: 6.15 | Y7: Pass | Z7: 6.7 | AA7: Pass
A8: 4 | B8: 4.3 | C8: 4.5 | D8: 4.1 | F8: 4.3 | H8: 4.2 | I8: Pass | J8: 4.1 | K8: Pass | L8: 5.1 | M8: Pass | N8: 4.9 | O8: Pass | P8: 5.2 | R8: 4.2 | S8: Pass | T8: 6.84 | U8: Pass | V8: 5.28 | W8: Pass | X8: 4.89 | Y8: Pass | Z8: 6.9 | AA8: Pass
A9: 5 | B9: 4.5 | C9: 4.7 | D9: 5.1 | F9: 4.4 | H9: 4.2 | I9: Pass | J9: 4.6 | K9: Pass | L9: 5.6 | M9: Pass | N9: 4.2 | O9: Pass | P9: 5.6 | R9: 5.2 | S9: Pass | T9: 7.64 | U9: Pass | V9: 6.92 | W9: Pass | X9: 6.23 | Y9: Pass | Z9: 7.4 | AA9: Pass
A10: 6 | B10: 4.2 | C10: 4.1 | D10: 4.2 | F10: 4.3 | H10: 4 | I10: Pass | J10: 4.4 | K10: Pass | L10: 5.4 | M10: Pass | N10: 5 | O10: Pass | P10: 5.2 | R10: 4.8 | S10: Pass | T10: 10 | U10: Warning | V10: 5.96 | W10: Pass | X10: 5.76 | Y10: Pass | Z10: 6.3 | AA10: Pass
A11: 7 | B11: 4.2 | C11: 4.4 | D11: 6.4 | F11: 4.3 | H11: 4.1 | I11: Pass | J11: 4.2 | K11: Pass | L11: 5.1 | M11: Pass | N11: 4.7 | O11: Pass | P11: 6 | R11: 4.7 | S11: Pass | T11: 9.61 | U11: Warning | V11: 7.54 | W11: Pass | X11: 5.92 | Y11: Pass | Z11: 7 | AA11: Pass
A12: 8 | B12: 4.1 | C12: 4.7 | D12: 4.7 | F12: 5.1 | H12: 4.1 | I12: Pass | J12: 4.7 | K12: Pass | L12: 5.2 | M12: Pass | N12: 4.5 | O12: Pass | P12: 5.3 | R12: 4.9 | S12: Pass | T12: 7.17 | U12: Pass | V12: 6.93 | W12: Pass | X12: 6.44 | Y12: Pass | Z12: 6.4 | AA12: Pass
A13: 9 | B13: 4.5 | C13: 4.1 | D13: 6.4 | F13: 4.4 | H13: 5.1 | I13: Pass | J13: 5 | K13: Pass | L13: 5.2 | M13: Pass | N13: 5.4 | O13: Pass | P13: 6.2 | R13: 5.3 | S13: Pass | T13: 8.54 | U13: Pass | V13: 6.17 | W13: Pass | X13: 6.12 | Y13: Pass | Z13: 6.4 | AA13: Pass
A14: 10 | B14: 4.6 | C14: 4.1 | D14: 6.6 | F14: 4.6 | H14: 4.7 | I14: Pass | J14: 4.5 | K14: Pass | L14: 5.5 | M14: Pass | N14: 4.6 | O14: Pass | P14: 5.8 | R14: 4.8 | S14: Pass | T14: 6.98 | U14: Pass | V14: 6.02 | W14: Pass | X14: 5.99 | Y14: Pass | Z14: 6.6 | AA14: Pass
A15: 11 | B15: 5 | C15: 4.2 | D15: 4.5 | F15: 4.6 | H15: 4.9 | I15: Pass | J15: 4.7 | K15: Pass | L15: 5.5 | M15: Pass | N15: 5 | O15: Pass | P15: 5.8 | R15: 4.4 | S15: Pass | T15: 8.32 | U15: Pass | V15: 5.98 | W15: Pass | X15: 5.57 | Y15: Pass | Z15: 6.4 | AA15: Pass
A16: 12 | B16: 4.4 | C16: 4.9 | D16: 5.4 | F16: 4.8 | H16: 4.6 | I16: Pass | J16: 4.7 | K16: Pass | L16: 5.1 | M16: Pass | N16: 5.1 | O16: Pass | P16: 5.6 | R16: 4.6 | S16: Pass | T16: 8.96 | U16: Pass | V16: 6.06 | W16: Pass | X16: 6.09 | Y16: Pass | Z16: 7.5 | AA16: Pass
... A24: 20 | B24: 4 | C24: 3.9 | D24: 4.7 | F24: 4.5 | H24: 4.5 | I24: Pass | J24: 5.6 | K24: Pass | L24: 5.5 | M24: Pass | N24: 4.5 | O24: Pass | P24: 5.2 | R24: 5 | S24: Pass | T24: 7.74 | U24: Pass | V24: 6.66 | W24: Pass | X24: 6.46 | Y24: Pass | Z24: 5.9 | AA24: Pass
A25: 21 | B25: 4.3 | C25: 4.5 | D25: 4.7 | F25: 4.8 | H25: 5.3 | I25: Pass | J25: 5.4 | K25: Pass | L25: 5.4 | M25: Pass | N25: 4.7 | O25: Pass | P25: 10.6 | Q25: Warning | R25: 5 | S25: Pass | T25: 7.67 | U25: Pass | V25: 5.75 | W25: Pass | X25: 5.67 | Y25: Pass | Z25: 6.5 | AA25: Pass
A26: 22 | B26: 4.6 | C26: 3.8 | D26: 4.7 | F26: 4.3 | H26: 4.7 | I26: Pass | J26: 5 | K26: Pass | L26: 5.3 | M26: Pass | N26: 4.8 | O26: Pass | P26: 6.2 | R26: 5 | S26: Pass | T26: 8.98 | U26: Pass | V26: 14.47 | W26: Fail | X26: 12.05 | Y26: Fail | Z26: 6.7 | AA26: Pass
A27: 23 | B27: 4.3 | C27: 4.9 | D27: 5.3 | F27: 4.4 | H27: 4.5 | I27: Pass | J27: 4.9 | K27: Pass | L27: 5.2 | M27: Pass | N27: 5.3 | O27: Pass | P27: 5.4 | R27: 4.7 | S27: Pass | T27: 7.46 | U27: Pass | V27: 5.65 | W27: Pass | X27: 5.53 | Y27: Pass | Z27: 8.6 | AA27: Pass
A28: 24 | B28: 4.3 | C28: 4.6 | D28: 4.5 | F28: 4.6 | H28: 4.1 | I28: Pass | J28: 4.4 | K28: Pass | L28: 5.2 | M28: Pass | N28: 5.3 | O28: Pass | P28: 5.6 | R28: 4.9 | S28: Pass | T28: 10.37 | U28: Warning | V28: 6.41 | W28: Pass | X28: 5.97 | Y28: Pass | Z28: 6.8 | AA28: Pass
A29: 25 | B29: 4.2 | C29: 4.3 | D29: 4.7 | F29: 4.3 | H29: 4.2 | I29: Pass | J29: 4.3 | K29: Pass | L29: 5.3 | M29: Pass | N29: 4.7 | O29: Pass | P29: 6.2 | R29: 4.6 | S29: Pass | T29: 8.59 | U29: Pass | V29: 5.96 | W29: Pass | X29: 5.83 | Y29: Pass | Z29: 6.8 | AA29: Pass
A30: 26 | B30: 4.3 | C30: 4.3 | D30: 4.6 | F30: 4.5 | H30: 4.2 | I30: Pass | J30: 4.4 | K30: Pass | L30: 5.3 | M30: Pass | N30: 4.5 | O30: Pass | P30: 5.9 | R30: 4.8 | S30: Pass | T30: 7.14 | U30: Pass | V30: 6.81 | W30: Pass | X30: 5.77 | Y30: Pass | Z30: 6.8 | AA30: Pass
A31: 27 | B31: 4.2 | C31: 4.1 | D31: 4.2 | F31: 4.4 | H31: 4.2 | I31: Pass | J31: 4.4 | K31: Pass | L31: 5.1 | M31: Pass | N31: 4.7 | O31: Pass | P31: 5.8 | R31: 4.7 | S31: Pass | T31: 8.63 | U31: Pass | V31: 6.19 | W31: Pass | X31: 5.8 | Y31: Pass | Z31: 7.1 | AA31: Pass
A32: 28 | B32: 4.1 | C32: 3.8 | D32: 4.8 | F32: 4.6 | H32: 4.4 | I32: Pass | J32: 4.8 | K32: Pass | L32: 5 | M32: Pass | N32: 4.5 | O32: Pass | P32: 6.6 | R32: 4.8 | S32: Pass | T32: 12.38 | U32: Fail | V32: 6.31 | W32: Pass | X32: 6.27 | Y32: Pass | Z32: 6 | AA32: Pass
A33: 29 | B33: 4.4 | C33: 4.1 | D33: 5 | F33: 4.5 | H33: 5.7 | I33: Pass | J33: 4.8 | K33: Pass | L33: 5.1 | M33: Pass | N33: 4.8 | O33: Pass | P33: 7 | R33: 4.6 | S33: Pass | T33: 8.33 | U33: Pass | V33: 5.66 | W33: Pass | X33: 5.23 | Y33: Pass | Z33: 5.5 | AA33: Pass
A34: 30 | B34: 4.1 | C34: 4.3 | D34: 4.6 | F34: 4.4 | H34: 4.5 | I34: Pass | J34: 5.1 | K34: Pass | L34: 5.2 | M34: Pass | N34: 5.3 | O34: Pass | P34: 5.7 | R34: 5 | S34: Pass | T34: 7.33 | U34: Pass | V34: 6.17 | W34: Pass | X34: 6.17 | Y34: Pass | Z34: 5.6 | AA34: Pass
A35: 31 | B35: 4.2 | C35: 3.9 | D35: 5 | F35: 4.5 | H35: 4.2 | I35: Pass | J35: 5 | K35: Pass | L35: 5.3 | M35: Pass | N35: 4.8 | O35: Pass | P35: 5.6 | R35: 4.5 | S35: Pass | T35: 7.11 | U35: Pass | V35: 5.65 | W35: Pass | X35: 5.52 | Y35: Pass | Z35: 6.3 | AA35: Pass
A36: 32 | B36: 4.4 | C36: 4.7 | D36: 4.3 | F36: 4.2 | H36: 4.6 | I36: Pass | J36: 5 | K36: Pass | L36: 5.1 | M36: Pass | N36: 4.5 | O36: Pass | P36: 5.1 | R36: 5.1 | S36: Pass | T36: 7.36 | U36: Pass | V36: 5.8 | W36: Pass | X36: 5.89 | Y36: Pass | Z36: 5.7 | AA36: Pass
A37: 33 | B37: 4.4 | C37: 4 | D37: 4.6 | F37: 5.1 | H37: 4.6 | I37: Pass | J37: 5.2 | K37: Pass | L37: 4.9 | M37: Pass | N37: 5.1 | O37: Pass | P37: 6 | R37: 4.4 | S37: Pass | T37: 9999 | U37: Fail | V37: 5.34 | W37: Pass | X37: 5.28 | Y37: Pass | Z37: 7.3 | AA37: Pass
... A104: 100 | B104: 4.5 | C104: 4.1 | D104: 3.8 | F104: 4.3 | H104: 4.6 | I104: Pass | J104: 4.6 | K104: Pass | L104: 6.5 | M104: Pass | N104: 5.2 | O104: Pass | P104: 4.6 | R104: 6 | S104: Pass | T104: 5.62 | U104: Pass | V104: 8.15 | W104: Pass | X104: 6.7 | Y104: Pass | Z104: 21 | AA104: Fail
A105: 101 | B105: 10 | C105: 11.2 | E105: Battery reading did not come | F105: 10.6 | G105: Replaced on 2/2/2018 | H105: 4.6 | I105: Pass | J105: 4.8 | K105: Pass | L105: 6.1 | M105: Pass | N105: 5.4 | O105: Pass | P105: 4.9 | R105: 5.4 | S105: Pass | T105: 6.68 | U105: Pass | V105: 8.28 | W105: Pass | X105: 7.3 | Y105: Pass | Z105: 10.1 | AA105: Warning
A106: 102 | B106: 4.3 | C106: 4.3 | D106: 4 | F106: 4.5 | H106: 4.5 | I106: Pass | J106: 4.8 | K106: Pass | L106: 6 | M106: Pass | N106: 5.6 | O106: Pass | P106: 4.9 | R106: 5.7 | S106: Pass | T106: 5.92 | U106: Pass | V106: 19.89 | W106: Fail | X106: 7.1 | Y106: Pass | Z106: 7.7 | AA106: Pass
A107: 103 | B107: 4.3 | C107: 4 | D107: 3.7 | F107: 4.4 | H107: 4.3 | I107: Pass | J107: 4.6 | K107: Pass | L107: 6.2 | M107: Pass | N107: 5 | O107: Pass | P107: 5.1 | R107: 6.1 | S107: Pass | T107: 5.94 | U107: Pass | V107: 7.41 | W107: Pass | X107: 6.7 | Y107: Pass | Z107: 11.3 | AA107: Warning
A108: 104 | B108: 4.1 | C108: 3.9 | D108: 4 | F108: 4.3 | H108: 4.3 | I108: Pass | J108: 5.1 | K108: Pass | L108: 5.5 | M108: Pass | N108: 10.3 | O108: Pass | P108: 4.7 | R108: 5.3 | S108: Pass | T108: 6.2 | U108: Pass | V108: 5.49 | W108: Pass | X108: 8.4 | Y108: Pass | Z108: 7.3 | AA108: Pass
A109: 105 | B109: 4.2 | C109: 4.1 | D109: 3.5 | F109: 4.4 | H109: 4.5 | I109: Pass | J109: 4.8 | K109: Pass | L109: 7.9 | M109: Pass | N109: 5.7 | O109: Pass | P109: 4.5 | R109: 11.4 | S109: Warning | T109: 6.03 | U109: Pass | V109: 8.88 | W109: Pass | X109: 7.4 | Y109: Pass | Z109: 8.5 | AA109: Pass
A110: 106 | B110: 4.4 | C110: 4.4 | D110: 3.8 | F110: 4.6 | H110: 4.5 | I110: Pass | J110: 4.7 | K110: Pass | L110: 6.2 | M110: Pass | N110: 5.4 | O110: Pass | P110: 4.3 | R110: 5.9 | S110: Pass | T110: 5.47 | U110: Pass | V110: 10.57 | W110: Waring | X110: 10.8 | Y110: Warning | Z110: 11.3 | AA110: Warning
A111: 107 | B111: 4.4 | C111: 4.4 | D111: 3.8 | F111: 4.6 | H111: 4.7 | I111: Pass | J111: 4.7 | K111: Pass | L111: 5.9 | M111: Pass | N111: 5.2 | O111: Pass | P111: 4.7 | R111: 5.7 | S111: Pass | T111: 6.07 | U111: Pass | V111: 8.51 | W111: Pass | X111: 7.7 | Y111: Pass | Z111: 12 | AA111: Warning
A112: 108 | B112: 4.3 | C112: 4.5 | D112: 3.7 | F112: 4.4 | H112: 4.3 | I112: Pass | J112: 4.8 | K112: Pass | L112: 5.7 | M112: Pass | N112: 5.4 | O112: Pass | P112: 4.6 | R112: 5.3 | S112: Pass | T112: 5.66 | U112: Pass | V112: 10.05 | W112: Warning | X112: 9.7 | Y112: Warning | Z112: 8.1 | AA112: Pass
